[07/Sep/2018 15:20:17] "GET /admin/ HTTP/1.1" 200 7473
[07/Sep/2018 15:20:18] "GET /admin/subway/admins/ HTTP/1.1" 200 4602
[07/Sep/2018 15:20:18] "GET /admin/jsi18n/ HTTP/1.1" 200 3185
[07/Sep/2018 15:20:20] "GET /admin/ HTTP/1.1" 200 7473
[07/Sep/2018 15:20:21] "GET /admin/subway/subwaylandmarkpoint/ HTTP/1.1" 200 5857
[07/Sep/2018 15:20:21] "GET /admin/jsi18n/ HTTP/1.1" 200 3185
Internal Server Error: /admin/subway/subwaylandmarkpoint/23/change/
Traceback (most recent call last):
  File "/usr/local/lib/python3.4/site-packages/django/db/backends/utils.py", line 85, in _execute
    return self.cursor.execute(sql, params)
  File "/usr/local/lib/python3.4/site-packages/django/db/backends/sqlite3/base.py", line 303, in execute
    return Database.Cursor.execute(self, query, params)
sqlite3.OperationalError: no such column: subway_subway.eng_name

The above exception was the direct cause of the following exception:

Traceback (most recent call last):
  File "/usr/local/lib/python3.4/site-packages/django/core/handlers/exception.py", line 35, in inner
    response = get_response(request)
  File "/usr/local/lib/python3.4/site-packages/django/core/handlers/base.py", line 158, in _get_response
    response = self.process_exception_by_middleware(e, request)
  File "/usr/local/lib/python3.4/site-packages/django/core/handlers/base.py", line 156, in _get_response
    response = response.render()
  File "/usr/local/lib/python3.4/site-packages/django/template/response.py", line 106, in render
    self.content = self.rendered_content
  File "/usr/local/lib/python3.4/site-packages/django/template/response.py", line 83, in rendered_content
    content = template.render(context, self._request)
  File "/usr/local/lib/python3.4/site-packages/django/template/backends/django.py", line 61, in render
    return self.template.render(context)
  File "/usr/local/lib/python3.4/site-packages/django/template/base.py", line 175, in render
    return self._render(context)
  File "/usr/local/lib/python3.4/site-packages/django/template/base.py", line 167, in _render
    return self.nodelist.render(context)
  File "/usr/local/lib/python3.4/site-packages/django/template/base.py", line 943, in render
    bit = node.render_annotated(context)
  File "/usr/local/lib/python3.4/site-packages/django/template/base.py", line 910, in render_annotated
    return self.render(context)
  File "/usr/local/lib/python3.4/site-packages/django/template/loader_tags.py", line 155, in render
    return compiled_parent._render(context)
  File "/usr/local/lib/python3.4/site-packages/django/template/base.py", line 167, in _render
    return self.nodelist.render(context)
  File "/usr/local/lib/python3.4/site-packages/django/template/base.py", line 943, in render
    bit = node.render_annotated(context)
  File "/usr/local/lib/python3.4/site-packages/django/template/base.py", line 910, in render_annotated
    return self.render(context)
  File "/usr/local/lib/python3.4/site-packages/django/template/loader_tags.py", line 155, in render
    return compiled_parent._render(context)
  File "/usr/local/lib/python3.4/site-packages/django/template/base.py", line 167, in _render
    return self.nodelist.render(context)
  File "/usr/local/lib/python3.4/site-packages/django/template/base.py", line 943, in render
    bit = node.render_annotated(context)
  File "/usr/local/lib/python3.4/site-packages/django/template/base.py", line 910, in render_annotated
    return self.render(context)
  File "/usr/local/lib/python3.4/site-packages/django/template/loader_tags.py", line 67, in render
    result = block.nodelist.render(context)
  File "/usr/local/lib/python3.4/site-packages/django/template/base.py", line 943, in render
    bit = node.render_annotated(context)
  File "/usr/local/lib/python3.4/site-packages/django/template/base.py", line 910, in render_annotated
    return self.render(context)
  File "/usr/local/lib/python3.4/site-packages/django/template/loader_tags.py", line 67, in render
    result = block.nodelist.render(context)
  File "/usr/local/lib/python3.4/site-packages/django/template/base.py", line 943, in render
    bit = node.render_annotated(context)
  File "/usr/local/lib/python3.4/site-packages/django/template/base.py", line 910, in render_annotated
    return self.render(context)
  File "/usr/local/lib/python3.4/site-packages/django/template/defaulttags.py", line 211, in render
    nodelist.append(node.render_annotated(context))
  File "/usr/local/lib/python3.4/site-packages/django/template/base.py", line 910, in render_annotated
    return self.render(context)
  File "/usr/local/lib/python3.4/site-packages/django/template/loader_tags.py", line 194, in render
    return template.render(context)
  File "/usr/local/lib/python3.4/site-packages/django/template/base.py", line 177, in render
    return self._render(context)
  File "/usr/local/lib/python3.4/site-packages/django/template/base.py", line 167, in _render
    return self.nodelist.render(context)
  File "/usr/local/lib/python3.4/site-packages/django/template/base.py", line 943, in render
    bit = node.render_annotated(context)
  File "/usr/local/lib/python3.4/site-packages/django/template/base.py", line 910, in render_annotated
    return self.render(context)
  File "/usr/local/lib/python3.4/site-packages/django/template/defaulttags.py", line 211, in render
    nodelist.append(node.render_annotated(context))
  File "/usr/local/lib/python3.4/site-packages/django/template/base.py", line 910, in render_annotated
    return self.render(context)
  File "/usr/local/lib/python3.4/site-packages/django/template/defaulttags.py", line 211, in render
    nodelist.append(node.render_annotated(context))
  File "/usr/local/lib/python3.4/site-packages/django/template/base.py", line 910, in render_annotated
    return self.render(context)
  File "/usr/local/lib/python3.4/site-packages/django/template/defaulttags.py", line 314, in render
    return nodelist.render(context)
  File "/usr/local/lib/python3.4/site-packages/django/template/base.py", line 943, in render
    bit = node.render_annotated(context)
  File "/usr/local/lib/python3.4/site-packages/django/template/base.py", line 910, in render_annotated
    return self.render(context)
  File "/usr/local/lib/python3.4/site-packages/django/template/defaulttags.py", line 314, in render
    return nodelist.render(context)
  File "/usr/local/lib/python3.4/site-packages/django/template/base.py", line 943, in render
    bit = node.render_annotated(context)
  File "/usr/local/lib/python3.4/site-packages/django/template/base.py", line 910, in render_annotated
    return self.render(context)
  File "/usr/local/lib/python3.4/site-packages/django/template/base.py", line 999, in render
    return render_value_in_context(output, context)
  File "/usr/local/lib/python3.4/site-packages/django/template/base.py", line 978, in render_value_in_context
    value = str(value)
  File "/usr/local/lib/python3.4/site-packages/django/utils/html.py", line 380, in <lambda>
    klass.__str__ = lambda self: mark_safe(klass_str(self))
  File "/usr/local/lib/python3.4/site-packages/django/forms/boundfield.py", line 36, in __str__
    return self.as_widget()
  File "/usr/local/lib/python3.4/site-packages/django/forms/boundfield.py", line 118, in as_widget
    **kwargs
  File "/usr/local/lib/python3.4/site-packages/django/forms/widgets.py", line 234, in render
    context = self.get_context(name, value, attrs)
  File "/usr/local/lib/python3.4/site-packages/django/contrib/admin/widgets.py", line 295, in get_context
    'rendered_widget': self.widget.render(name, value, attrs),
  File "/usr/local/lib/python3.4/site-packages/django/forms/widgets.py", line 234, in render
    context = self.get_context(name, value, attrs)
  File "/usr/local/lib/python3.4/site-packages/django/forms/widgets.py", line 677, in get_context
    context = super().get_context(name, value, attrs)
  File "/usr/local/lib/python3.4/site-packages/django/forms/widgets.py", line 637, in get_context
    context['widget']['optgroups'] = self.optgroups(name, context['widget']['value'], attrs)
  File "/usr/local/lib/python3.4/site-packages/django/forms/widgets.py", line 585, in optgroups
    for index, (option_value, option_label) in enumerate(self.choices):
  File "/usr/local/lib/python3.4/site-packages/django/forms/models.py", line 1140, in __iter__
    for obj in queryset:
  File "/usr/local/lib/python3.4/site-packages/django/db/models/query.py", line 336, in _iterator
    yield from self._iterable_class(self, chunked_fetch=use_chunked_fetch, chunk_size=chunk_size)
  File "/usr/local/lib/python3.4/site-packages/django/db/models/query.py", line 53, in __iter__
    results = compiler.execute_sql(chunked_fetch=self.chunked_fetch, chunk_size=self.chunk_size)
  File "/usr/local/lib/python3.4/site-packages/django/db/models/sql/compiler.py", line 1066, in execute_sql
    cursor.execute(sql, params)
  File "/usr/local/lib/python3.4/site-packages/django/db/backends/utils.py", line 100, in execute
    return super().execute(sql, params)
  File "/usr/local/lib/python3.4/site-packages/django/db/backends/utils.py", line 68, in execute
    return self._execute_with_wrappers(sql, params, many=False, executor=self._execute)
  File "/usr/local/lib/python3.4/site-packages/django/db/backends/utils.py", line 77, in _execute_with_wrappers
    return executor(sql, params, many, context)
  File "/usr/local/lib/python3.4/site-packages/django/db/backends/utils.py", line 85, in _execute
    return self.cursor.execute(sql, params)
  File "/usr/local/lib/python3.4/site-packages/django/db/utils.py", line 89, in __exit__
    raise dj_exc_value.with_traceback(traceback) from exc_value
  File "/usr/local/lib/python3.4/site-packages/django/db/backends/utils.py", line 85, in _execute
    return self.cursor.execute(sql, params)
  File "/usr/local/lib/python3.4/site-packages/django/db/backends/sqlite3/base.py", line 303, in execute
    return Database.Cursor.execute(self, query, params)
django.db.utils.OperationalError: no such column: subway_subway.eng_name
[07/Sep/2018 15:20:22] "GET /admin/subway/subwaylandmarkpoint/23/change/ HTTP/1.1" 500 500352
[07/Sep/2018 15:20:26] "GET /admin/subway/subwaylandmarkpoint/ HTTP/1.1" 200 5857
Internal Server Error: /insert
Traceback (most recent call last):
  File "/usr/local/lib/python3.4/site-packages/django/db/backends/utils.py", line 85, in _execute
    return self.cursor.execute(sql, params)
  File "/usr/local/lib/python3.4/site-packages/django/db/backends/sqlite3/base.py", line 303, in execute
    return Database.Cursor.execute(self, query, params)
sqlite3.OperationalError: table subway_subway has no column named eng_name

The above exception was the direct cause of the following exception:

Traceback (most recent call last):
  File "/usr/local/lib/python3.4/site-packages/django/core/handlers/exception.py", line 35, in inner
    response = get_response(request)
  File "/usr/local/lib/python3.4/site-packages/django/core/handlers/base.py", line 128, in _get_response
    response = self.process_exception_by_middleware(e, request)
  File "/usr/local/lib/python3.4/site-packages/django/core/handlers/base.py", line 126, in _get_response
    response = wrapped_callback(request, *callback_args, **callback_kwargs)
  File "/home/ubuntu/myproject/subway/views.py", line 157, in insert_station_datas
    Subway().insert_stations(data, line, station)
  File "/home/ubuntu/myproject/subway/models.py", line 37, in insert_stations
    self.save()
  File "/usr/local/lib/python3.4/site-packages/django/db/models/base.py", line 729, in save
    force_update=force_update, update_fields=update_fields)
  File "/usr/local/lib/python3.4/site-packages/django/db/models/base.py", line 759, in save_base
    updated = self._save_table(raw, cls, force_insert, force_update, using, update_fields)
  File "/usr/local/lib/python3.4/site-packages/django/db/models/base.py", line 842, in _save_table
    result = self._do_insert(cls._base_manager, using, fields, update_pk, raw)
  File "/usr/local/lib/python3.4/site-packages/django/db/models/base.py", line 880, in _do_insert
    using=using, raw=raw)
  File "/usr/local/lib/python3.4/site-packages/django/db/models/manager.py", line 82, in manager_method
    return getattr(self.get_queryset(), name)(*args, **kwargs)
  File "/usr/local/lib/python3.4/site-packages/django/db/models/query.py", line 1125, in _insert
    return query.get_compiler(using=using).execute_sql(return_id)
  File "/usr/local/lib/python3.4/site-packages/django/db/models/sql/compiler.py", line 1283, in execute_sql
    cursor.execute(sql, params)
  File "/usr/local/lib/python3.4/site-packages/django/db/backends/utils.py", line 100, in execute
    return super().execute(sql, params)
  File "/usr/local/lib/python3.4/site-packages/django/db/backends/utils.py", line 68, in execute
    return self._execute_with_wrappers(sql, params, many=False, executor=self._execute)
  File "/usr/local/lib/python3.4/site-packages/django/db/backends/utils.py", line 77, in _execute_with_wrappers
    return executor(sql, params, many, context)
  File "/usr/local/lib/python3.4/site-packages/django/db/backends/utils.py", line 85, in _execute
    return self.cursor.execute(sql, params)
  File "/usr/local/lib/python3.4/site-packages/django/db/utils.py", line 89, in __exit__
    raise dj_exc_value.with_traceback(traceback) from exc_value
  File "/usr/local/lib/python3.4/site-packages/django/db/backends/utils.py", line 85, in _execute
    return self.cursor.execute(sql, params)
  File "/usr/local/lib/python3.4/site-packages/django/db/backends/sqlite3/base.py", line 303, in execute
    return Database.Cursor.execute(self, query, params)
django.db.utils.OperationalError: table subway_subway has no column named eng_name
[07/Sep/2018 15:20:36] "GET /insert HTTP/1.1" 500 161374
[07/Sep/2018 15:20:40] "GET /admin/subway/subwaylandmarkpoint/ HTTP/1.1" 200 5857
[07/Sep/2018 15:20:46] "GET /admin/ HTTP/1.1" 200 7473
Internal Server Error: /admin/subway/subway/
Traceback (most recent call last):
  File "/usr/local/lib/python3.4/site-packages/django/db/backends/utils.py", line 85, in _execute
    return self.cursor.execute(sql, params)
  File "/usr/local/lib/python3.4/site-packages/django/db/backends/sqlite3/base.py", line 303, in execute
    return Database.Cursor.execute(self, query, params)
sqlite3.OperationalError: no such column: subway_subway.eng_name

The above exception was the direct cause of the following exception:

Traceback (most recent call last):
  File "/usr/local/lib/python3.4/site-packages/django/core/handlers/exception.py", line 35, in inner
    response = get_response(request)
  File "/usr/local/lib/python3.4/site-packages/django/core/handlers/base.py", line 128, in _get_response
    response = self.process_exception_by_middleware(e, request)
  File "/usr/local/lib/python3.4/site-packages/django/core/handlers/base.py", line 126, in _get_response
    response = wrapped_callback(request, *callback_args, **callback_kwargs)
  File "/usr/local/lib/python3.4/site-packages/django/contrib/admin/options.py", line 574, in wrapper
    return self.admin_site.admin_view(view)(*args, **kwargs)
  File "/usr/local/lib/python3.4/site-packages/django/utils/decorators.py", line 142, in _wrapped_view
    response = view_func(request, *args, **kwargs)
  File "/usr/local/lib/python3.4/site-packages/django/views/decorators/cache.py", line 44, in _wrapped_view_func
    response = view_func(request, *args, **kwargs)
  File "/usr/local/lib/python3.4/site-packages/django/contrib/admin/sites.py", line 223, in inner
    return view(request, *args, **kwargs)
  File "/usr/local/lib/python3.4/site-packages/django/utils/decorators.py", line 62, in _wrapper
    return bound_func(*args, **kwargs)
  File "/usr/local/lib/python3.4/site-packages/django/utils/decorators.py", line 142, in _wrapped_view
    response = view_func(request, *args, **kwargs)
  File "/usr/local/lib/python3.4/site-packages/django/utils/decorators.py", line 58, in bound_func
    return func.__get__(self, type(self))(*args2, **kwargs2)
  File "/usr/local/lib/python3.4/site-packages/django/contrib/admin/options.py", line 1685, in changelist_view
    selection_note=_('0 of %(cnt)s selected') % {'cnt': len(cl.result_list)},
  File "/usr/local/lib/python3.4/site-packages/django/db/models/query.py", line 254, in __len__
    self._fetch_all()
  File "/usr/local/lib/python3.4/site-packages/django/db/models/query.py", line 1179, in _fetch_all
    self._result_cache = list(self._iterable_class(self))
  File "/usr/local/lib/python3.4/site-packages/django/db/models/query.py", line 53, in __iter__
    results = compiler.execute_sql(chunked_fetch=self.chunked_fetch, chunk_size=self.chunk_size)
  File "/usr/local/lib/python3.4/site-packages/django/db/models/sql/compiler.py", line 1066, in execute_sql
    cursor.execute(sql, params)
  File "/usr/local/lib/python3.4/site-packages/django/db/backends/utils.py", line 100, in execute
    return super().execute(sql, params)
  File "/usr/local/lib/python3.4/site-packages/django/db/backends/utils.py", line 68, in execute
    return self._execute_with_wrappers(sql, params, many=False, executor=self._execute)
  File "/usr/local/lib/python3.4/site-packages/django/db/backends/utils.py", line 77, in _execute_with_wrappers
    return executor(sql, params, many, context)
  File "/usr/local/lib/python3.4/site-packages/django/db/backends/utils.py", line 85, in _execute
    return self.cursor.execute(sql, params)
  File "/usr/local/lib/python3.4/site-packages/django/db/utils.py", line 89, in __exit__
    raise dj_exc_value.with_traceback(traceback) from exc_value
  File "/usr/local/lib/python3.4/site-packages/django/db/backends/utils.py", line 85, in _execute
    return self.cursor.execute(sql, params)
  File "/usr/local/lib/python3.4/site-packages/django/db/backends/sqlite3/base.py", line 303, in execute
    return Database.Cursor.execute(self, query, params)
django.db.utils.OperationalError: no such column: subway_subway.eng_name
[07/Sep/2018 15:20:48] "GET /admin/subway/subway/ HTTP/1.1" 500 162031
[07/Sep/2018 15:29:51] "GET /admin/ HTTP/1.1" 200 7473
[07/Sep/2018 15:29:52] "GET /admin/ HTTP/1.1" 200 7473
[07/Sep/2018 15:29:55] "GET /admin/subway/subwaylandmarkpoint/ HTTP/1.1" 200 5857
[07/Sep/2018 15:29:55] "GET /admin/jsi18n/ HTTP/1.1" 200 3185
[07/Sep/2018 15:29:56] "GET /admin/ HTTP/1.1" 200 7473
[07/Sep/2018 15:30:00] "GET /admin/subway/subway/add/ HTTP/1.1" 200 8509
[07/Sep/2018 15:30:00] "GET /static/admin/css/forms.css HTTP/1.1" 200 8173
[07/Sep/2018 15:30:00] "GET /admin/jsi18n/ HTTP/1.1" 200 3185
[07/Sep/2018 15:30:00] "GET /static/admin/js/change_form.js HTTP/1.1" 200 712
[07/Sep/2018 15:30:00] "GET /static/admin/js/prepopulate_init.js HTTP/1.1" 200 495
[07/Sep/2018 15:30:00] "GET /static/admin/css/widgets.css HTTP/1.1" 200 10340
[07/Sep/2018 15:30:09] "GET /admin/ HTTP/1.1" 200 7473
Internal Server Error: /admin/subway/subwaylandmarkpoint/add/
Traceback (most recent call last):
  File "/usr/local/lib/python3.4/site-packages/django/db/backends/utils.py", line 85, in _execute
    return self.cursor.execute(sql, params)
  File "/usr/local/lib/python3.4/site-packages/django/db/backends/sqlite3/base.py", line 303, in execute
    return Database.Cursor.execute(self, query, params)
sqlite3.OperationalError: no such column: subway_subway.eng_name

The above exception was the direct cause of the following exception:

Traceback (most recent call last):
  File "/usr/local/lib/python3.4/site-packages/django/core/handlers/exception.py", line 35, in inner
    response = get_response(request)
  File "/usr/local/lib/python3.4/site-packages/django/core/handlers/base.py", line 158, in _get_response
    response = self.process_exception_by_middleware(e, request)
  File "/usr/local/lib/python3.4/site-packages/django/core/handlers/base.py", line 156, in _get_response
    response = response.render()
  File "/usr/local/lib/python3.4/site-packages/django/template/response.py", line 106, in render
    self.content = self.rendered_content
  File "/usr/local/lib/python3.4/site-packages/django/template/response.py", line 83, in rendered_content
    content = template.render(context, self._request)
  File "/usr/local/lib/python3.4/site-packages/django/template/backends/django.py", line 61, in render
    return self.template.render(context)
  File "/usr/local/lib/python3.4/site-packages/django/template/base.py", line 175, in render
    return self._render(context)
  File "/usr/local/lib/python3.4/site-packages/django/template/base.py", line 167, in _render
    return self.nodelist.render(context)
  File "/usr/local/lib/python3.4/site-packages/django/template/base.py", line 943, in render
    bit = node.render_annotated(context)
  File "/usr/local/lib/python3.4/site-packages/django/template/base.py", line 910, in render_annotated
    return self.render(context)
  File "/usr/local/lib/python3.4/site-packages/django/template/loader_tags.py", line 155, in render
    return compiled_parent._render(context)
  File "/usr/local/lib/python3.4/site-packages/django/template/base.py", line 167, in _render
    return self.nodelist.render(context)
  File "/usr/local/lib/python3.4/site-packages/django/template/base.py", line 943, in render
    bit = node.render_annotated(context)
  File "/usr/local/lib/python3.4/site-packages/django/template/base.py", line 910, in render_annotated
    return self.render(context)
  File "/usr/local/lib/python3.4/site-packages/django/template/loader_tags.py", line 155, in render
    return compiled_parent._render(context)
  File "/usr/local/lib/python3.4/site-packages/django/template/base.py", line 167, in _render
    return self.nodelist.render(context)
  File "/usr/local/lib/python3.4/site-packages/django/template/base.py", line 943, in render
    bit = node.render_annotated(context)
  File "/usr/local/lib/python3.4/site-packages/django/template/base.py", line 910, in render_annotated
    return self.render(context)
  File "/usr/local/lib/python3.4/site-packages/django/template/loader_tags.py", line 67, in render
    result = block.nodelist.render(context)
  File "/usr/local/lib/python3.4/site-packages/django/template/base.py", line 943, in render
    bit = node.render_annotated(context)
  File "/usr/local/lib/python3.4/site-packages/django/template/base.py", line 910, in render_annotated
    return self.render(context)
  File "/usr/local/lib/python3.4/site-packages/django/template/loader_tags.py", line 67, in render
    result = block.nodelist.render(context)
  File "/usr/local/lib/python3.4/site-packages/django/template/base.py", line 943, in render
    bit = node.render_annotated(context)
  File "/usr/local/lib/python3.4/site-packages/django/template/base.py", line 910, in render_annotated
    return self.render(context)
  File "/usr/local/lib/python3.4/site-packages/django/template/defaulttags.py", line 211, in render
    nodelist.append(node.render_annotated(context))
  File "/usr/local/lib/python3.4/site-packages/django/template/base.py", line 910, in render_annotated
    return self.render(context)
  File "/usr/local/lib/python3.4/site-packages/django/template/loader_tags.py", line 194, in render
    return template.render(context)
  File "/usr/local/lib/python3.4/site-packages/django/template/base.py", line 177, in render
    return self._render(context)
  File "/usr/local/lib/python3.4/site-packages/django/template/base.py", line 167, in _render
    return self.nodelist.render(context)
  File "/usr/local/lib/python3.4/site-packages/django/template/base.py", line 943, in render
    bit = node.render_annotated(context)
  File "/usr/local/lib/python3.4/site-packages/django/template/base.py", line 910, in render_annotated
    return self.render(context)
  File "/usr/local/lib/python3.4/site-packages/django/template/defaulttags.py", line 211, in render
    nodelist.append(node.render_annotated(context))
  File "/usr/local/lib/python3.4/site-packages/django/template/base.py", line 910, in render_annotated
    return self.render(context)
  File "/usr/local/lib/python3.4/site-packages/django/template/defaulttags.py", line 211, in render
    nodelist.append(node.render_annotated(context))
  File "/usr/local/lib/python3.4/site-packages/django/template/base.py", line 910, in render_annotated
    return self.render(context)
  File "/usr/local/lib/python3.4/site-packages/django/template/defaulttags.py", line 314, in render
    return nodelist.render(context)
  File "/usr/local/lib/python3.4/site-packages/django/template/base.py", line 943, in render
    bit = node.render_annotated(context)
  File "/usr/local/lib/python3.4/site-packages/django/template/base.py", line 910, in render_annotated
    return self.render(context)
  File "/usr/local/lib/python3.4/site-packages/django/template/defaulttags.py", line 314, in render
    return nodelist.render(context)
  File "/usr/local/lib/python3.4/site-packages/django/template/base.py", line 943, in render
    bit = node.render_annotated(context)
  File "/usr/local/lib/python3.4/site-packages/django/template/base.py", line 910, in render_annotated
    return self.render(context)
  File "/usr/local/lib/python3.4/site-packages/django/template/base.py", line 999, in render
    return render_value_in_context(output, context)
  File "/usr/local/lib/python3.4/site-packages/django/template/base.py", line 978, in render_value_in_context
    value = str(value)
  File "/usr/local/lib/python3.4/site-packages/django/utils/html.py", line 380, in <lambda>
    klass.__str__ = lambda self: mark_safe(klass_str(self))
  File "/usr/local/lib/python3.4/site-packages/django/forms/boundfield.py", line 36, in __str__
    return self.as_widget()
  File "/usr/local/lib/python3.4/site-packages/django/forms/boundfield.py", line 118, in as_widget
    **kwargs
  File "/usr/local/lib/python3.4/site-packages/django/forms/widgets.py", line 234, in render
    context = self.get_context(name, value, attrs)
  File "/usr/local/lib/python3.4/site-packages/django/contrib/admin/widgets.py", line 295, in get_context
    'rendered_widget': self.widget.render(name, value, attrs),
  File "/usr/local/lib/python3.4/site-packages/django/forms/widgets.py", line 234, in render
    context = self.get_context(name, value, attrs)
  File "/usr/local/lib/python3.4/site-packages/django/forms/widgets.py", line 677, in get_context
    context = super().get_context(name, value, attrs)
  File "/usr/local/lib/python3.4/site-packages/django/forms/widgets.py", line 637, in get_context
    context['widget']['optgroups'] = self.optgroups(name, context['widget']['value'], attrs)
  File "/usr/local/lib/python3.4/site-packages/django/forms/widgets.py", line 585, in optgroups
    for index, (option_value, option_label) in enumerate(self.choices):
  File "/usr/local/lib/python3.4/site-packages/django/forms/models.py", line 1140, in __iter__
    for obj in queryset:
  File "/usr/local/lib/python3.4/site-packages/django/db/models/query.py", line 336, in _iterator
    yield from self._iterable_class(self, chunked_fetch=use_chunked_fetch, chunk_size=chunk_size)
  File "/usr/local/lib/python3.4/site-packages/django/db/models/query.py", line 53, in __iter__
    results = compiler.execute_sql(chunked_fetch=self.chunked_fetch, chunk_size=self.chunk_size)
  File "/usr/local/lib/python3.4/site-packages/django/db/models/sql/compiler.py", line 1066, in execute_sql
    cursor.execute(sql, params)
  File "/usr/local/lib/python3.4/site-packages/django/db/backends/utils.py", line 100, in execute
    return super().execute(sql, params)
  File "/usr/local/lib/python3.4/site-packages/django/db/backends/utils.py", line 68, in execute
    return self._execute_with_wrappers(sql, params, many=False, executor=self._execute)
  File "/usr/local/lib/python3.4/site-packages/django/db/backends/utils.py", line 77, in _execute_with_wrappers
    return executor(sql, params, many, context)
  File "/usr/local/lib/python3.4/site-packages/django/db/backends/utils.py", line 85, in _execute
    return self.cursor.execute(sql, params)
  File "/usr/local/lib/python3.4/site-packages/django/db/utils.py", line 89, in __exit__
    raise dj_exc_value.with_traceback(traceback) from exc_value
  File "/usr/local/lib/python3.4/site-packages/django/db/backends/utils.py", line 85, in _execute
    return self.cursor.execute(sql, params)
  File "/usr/local/lib/python3.4/site-packages/django/db/backends/sqlite3/base.py", line 303, in execute
    return Database.Cursor.execute(self, query, params)
django.db.utils.OperationalError: no such column: subway_subway.eng_name
[07/Sep/2018 15:30:12] "GET /admin/subway/subwaylandmarkpoint/add/ HTTP/1.1" 500 497124
[07/Sep/2018 15:30:19] "GET /admin/ HTTP/1.1" 200 7473
Internal Server Error: /admin/subway/subway/
Traceback (most recent call last):
  File "/usr/local/lib/python3.4/site-packages/django/db/backends/utils.py", line 85, in _execute
    return self.cursor.execute(sql, params)
  File "/usr/local/lib/python3.4/site-packages/django/db/backends/sqlite3/base.py", line 303, in execute
    return Database.Cursor.execute(self, query, params)
sqlite3.OperationalError: no such column: subway_subway.eng_name

The above exception was the direct cause of the following exception:

Traceback (most recent call last):
  File "/usr/local/lib/python3.4/site-packages/django/core/handlers/exception.py", line 35, in inner
    response = get_response(request)
  File "/usr/local/lib/python3.4/site-packages/django/core/handlers/base.py", line 128, in _get_response
    response = self.process_exception_by_middleware(e, request)
  File "/usr/local/lib/python3.4/site-packages/django/core/handlers/base.py", line 126, in _get_response
    response = wrapped_callback(request, *callback_args, **callback_kwargs)
  File "/usr/local/lib/python3.4/site-packages/django/contrib/admin/options.py", line 574, in wrapper
    return self.admin_site.admin_view(view)(*args, **kwargs)
  File "/usr/local/lib/python3.4/site-packages/django/utils/decorators.py", line 142, in _wrapped_view
    response = view_func(request, *args, **kwargs)
  File "/usr/local/lib/python3.4/site-packages/django/views/decorators/cache.py", line 44, in _wrapped_view_func
    response = view_func(request, *args, **kwargs)
  File "/usr/local/lib/python3.4/site-packages/django/contrib/admin/sites.py", line 223, in inner
    return view(request, *args, **kwargs)
  File "/usr/local/lib/python3.4/site-packages/django/utils/decorators.py", line 62, in _wrapper
    return bound_func(*args, **kwargs)
  File "/usr/local/lib/python3.4/site-packages/django/utils/decorators.py", line 142, in _wrapped_view
    response = view_func(request, *args, **kwargs)
  File "/usr/local/lib/python3.4/site-packages/django/utils/decorators.py", line 58, in bound_func
    return func.__get__(self, type(self))(*args2, **kwargs2)
  File "/usr/local/lib/python3.4/site-packages/django/contrib/admin/options.py", line 1685, in changelist_view
    selection_note=_('0 of %(cnt)s selected') % {'cnt': len(cl.result_list)},
  File "/usr/local/lib/python3.4/site-packages/django/db/models/query.py", line 254, in __len__
    self._fetch_all()
  File "/usr/local/lib/python3.4/site-packages/django/db/models/query.py", line 1179, in _fetch_all
    self._result_cache = list(self._iterable_class(self))
  File "/usr/local/lib/python3.4/site-packages/django/db/models/query.py", line 53, in __iter__
    results = compiler.execute_sql(chunked_fetch=self.chunked_fetch, chunk_size=self.chunk_size)
  File "/usr/local/lib/python3.4/site-packages/django/db/models/sql/compiler.py", line 1066, in execute_sql
    cursor.execute(sql, params)
  File "/usr/local/lib/python3.4/site-packages/django/db/backends/utils.py", line 100, in execute
    return super().execute(sql, params)
  File "/usr/local/lib/python3.4/site-packages/django/db/backends/utils.py", line 68, in execute
    return self._execute_with_wrappers(sql, params, many=False, executor=self._execute)
  File "/usr/local/lib/python3.4/site-packages/django/db/backends/utils.py", line 77, in _execute_with_wrappers
    return executor(sql, params, many, context)
  File "/usr/local/lib/python3.4/site-packages/django/db/backends/utils.py", line 85, in _execute
    return self.cursor.execute(sql, params)
  File "/usr/local/lib/python3.4/site-packages/django/db/utils.py", line 89, in __exit__
    raise dj_exc_value.with_traceback(traceback) from exc_value
  File "/usr/local/lib/python3.4/site-packages/django/db/backends/utils.py", line 85, in _execute
    return self.cursor.execute(sql, params)
  File "/usr/local/lib/python3.4/site-packages/django/db/backends/sqlite3/base.py", line 303, in execute
    return Database.Cursor.execute(self, query, params)
django.db.utils.OperationalError: no such column: subway_subway.eng_name
[07/Sep/2018 15:30:23] "GET /admin/subway/subway/ HTTP/1.1" 500 162026
[07/Sep/2018 15:30:25] "GET /admin/ HTTP/1.1" 200 7473
[07/Sep/2018 15:30:35] "GET /admin/subway/admins/ HTTP/1.1" 200 4602
[07/Sep/2018 15:30:35] "GET /admin/jsi18n/ HTTP/1.1" 200 3185
[07/Sep/2018 15:30:37] "GET /admin/ HTTP/1.1" 200 7473
Internal Server Error: /admin/subway/subway/
Traceback (most recent call last):
  File "/usr/local/lib/python3.4/site-packages/django/db/backends/utils.py", line 85, in _execute
    return self.cursor.execute(sql, params)
  File "/usr/local/lib/python3.4/site-packages/django/db/backends/sqlite3/base.py", line 303, in execute
    return Database.Cursor.execute(self, query, params)
sqlite3.OperationalError: no such column: subway_subway.eng_name

The above exception was the direct cause of the following exception:

Traceback (most recent call last):
  File "/usr/local/lib/python3.4/site-packages/django/core/handlers/exception.py", line 35, in inner
    response = get_response(request)
  File "/usr/local/lib/python3.4/site-packages/django/core/handlers/base.py", line 128, in _get_response
    response = self.process_exception_by_middleware(e, request)
  File "/usr/local/lib/python3.4/site-packages/django/core/handlers/base.py", line 126, in _get_response
    response = wrapped_callback(request, *callback_args, **callback_kwargs)
  File "/usr/local/lib/python3.4/site-packages/django/contrib/admin/options.py", line 574, in wrapper
    return self.admin_site.admin_view(view)(*args, **kwargs)
  File "/usr/local/lib/python3.4/site-packages/django/utils/decorators.py", line 142, in _wrapped_view
    response = view_func(request, *args, **kwargs)
  File "/usr/local/lib/python3.4/site-packages/django/views/decorators/cache.py", line 44, in _wrapped_view_func
    response = view_func(request, *args, **kwargs)
  File "/usr/local/lib/python3.4/site-packages/django/contrib/admin/sites.py", line 223, in inner
    return view(request, *args, **kwargs)
  File "/usr/local/lib/python3.4/site-packages/django/utils/decorators.py", line 62, in _wrapper
    return bound_func(*args, **kwargs)
  File "/usr/local/lib/python3.4/site-packages/django/utils/decorators.py", line 142, in _wrapped_view
    response = view_func(request, *args, **kwargs)
  File "/usr/local/lib/python3.4/site-packages/django/utils/decorators.py", line 58, in bound_func
    return func.__get__(self, type(self))(*args2, **kwargs2)
  File "/usr/local/lib/python3.4/site-packages/django/contrib/admin/options.py", line 1685, in changelist_view
    selection_note=_('0 of %(cnt)s selected') % {'cnt': len(cl.result_list)},
  File "/usr/local/lib/python3.4/site-packages/django/db/models/query.py", line 254, in __len__
    self._fetch_all()
  File "/usr/local/lib/python3.4/site-packages/django/db/models/query.py", line 1179, in _fetch_all
    self._result_cache = list(self._iterable_class(self))
  File "/usr/local/lib/python3.4/site-packages/django/db/models/query.py", line 53, in __iter__
    results = compiler.execute_sql(chunked_fetch=self.chunked_fetch, chunk_size=self.chunk_size)
  File "/usr/local/lib/python3.4/site-packages/django/db/models/sql/compiler.py", line 1066, in execute_sql
    cursor.execute(sql, params)
  File "/usr/local/lib/python3.4/site-packages/django/db/backends/utils.py", line 100, in execute
    return super().execute(sql, params)
  File "/usr/local/lib/python3.4/site-packages/django/db/backends/utils.py", line 68, in execute
    return self._execute_with_wrappers(sql, params, many=False, executor=self._execute)
  File "/usr/local/lib/python3.4/site-packages/django/db/backends/utils.py", line 77, in _execute_with_wrappers
    return executor(sql, params, many, context)
  File "/usr/local/lib/python3.4/site-packages/django/db/backends/utils.py", line 85, in _execute
    return self.cursor.execute(sql, params)
  File "/usr/local/lib/python3.4/site-packages/django/db/utils.py", line 89, in __exit__
    raise dj_exc_value.with_traceback(traceback) from exc_value
  File "/usr/local/lib/python3.4/site-packages/django/db/backends/utils.py", line 85, in _execute
    return self.cursor.execute(sql, params)
  File "/usr/local/lib/python3.4/site-packages/django/db/backends/sqlite3/base.py", line 303, in execute
    return Database.Cursor.execute(self, query, params)
django.db.utils.OperationalError: no such column: subway_subway.eng_name
[07/Sep/2018 15:30:42] "GET /admin/subway/subway/ HTTP/1.1" 500 162031
[07/Sep/2018 15:30:44] "GET /admin/ HTTP/1.1" 200 7473
Internal Server Error: /admin/subway/admins/add/
Traceback (most recent call last):
  File "/usr/local/lib/python3.4/site-packages/django/db/backends/utils.py", line 85, in _execute
    return self.cursor.execute(sql, params)
  File "/usr/local/lib/python3.4/site-packages/django/db/backends/sqlite3/base.py", line 303, in execute
    return Database.Cursor.execute(self, query, params)
sqlite3.OperationalError: no such column: subway_subway.eng_name

The above exception was the direct cause of the following exception:

Traceback (most recent call last):
  File "/usr/local/lib/python3.4/site-packages/django/core/handlers/exception.py", line 35, in inner
    response = get_response(request)
  File "/usr/local/lib/python3.4/site-packages/django/core/handlers/base.py", line 158, in _get_response
    response = self.process_exception_by_middleware(e, request)
  File "/usr/local/lib/python3.4/site-packages/django/core/handlers/base.py", line 156, in _get_response
    response = response.render()
  File "/usr/local/lib/python3.4/site-packages/django/template/response.py", line 106, in render
    self.content = self.rendered_content
  File "/usr/local/lib/python3.4/site-packages/django/template/response.py", line 83, in rendered_content
    content = template.render(context, self._request)
  File "/usr/local/lib/python3.4/site-packages/django/template/backends/django.py", line 61, in render
    return self.template.render(context)
  File "/usr/local/lib/python3.4/site-packages/django/template/base.py", line 175, in render
    return self._render(context)
  File "/usr/local/lib/python3.4/site-packages/django/template/base.py", line 167, in _render
    return self.nodelist.render(context)
  File "/usr/local/lib/python3.4/site-packages/django/template/base.py", line 943, in render
    bit = node.render_annotated(context)
  File "/usr/local/lib/python3.4/site-packages/django/template/base.py", line 910, in render_annotated
    return self.render(context)
  File "/usr/local/lib/python3.4/site-packages/django/template/loader_tags.py", line 155, in render
    return compiled_parent._render(context)
  File "/usr/local/lib/python3.4/site-packages/django/template/base.py", line 167, in _render
    return self.nodelist.render(context)
  File "/usr/local/lib/python3.4/site-packages/django/template/base.py", line 943, in render
    bit = node.render_annotated(context)
  File "/usr/local/lib/python3.4/site-packages/django/template/base.py", line 910, in render_annotated
    return self.render(context)
  File "/usr/local/lib/python3.4/site-packages/django/template/loader_tags.py", line 155, in render
    return compiled_parent._render(context)
  File "/usr/local/lib/python3.4/site-packages/django/template/base.py", line 167, in _render
    return self.nodelist.render(context)
  File "/usr/local/lib/python3.4/site-packages/django/template/base.py", line 943, in render
    bit = node.render_annotated(context)
  File "/usr/local/lib/python3.4/site-packages/django/template/base.py", line 910, in render_annotated
    return self.render(context)
  File "/usr/local/lib/python3.4/site-packages/django/template/loader_tags.py", line 67, in render
    result = block.nodelist.render(context)
  File "/usr/local/lib/python3.4/site-packages/django/template/base.py", line 943, in render
    bit = node.render_annotated(context)
  File "/usr/local/lib/python3.4/site-packages/django/template/base.py", line 910, in render_annotated
    return self.render(context)
  File "/usr/local/lib/python3.4/site-packages/django/template/loader_tags.py", line 67, in render
    result = block.nodelist.render(context)
  File "/usr/local/lib/python3.4/site-packages/django/template/base.py", line 943, in render
    bit = node.render_annotated(context)
  File "/usr/local/lib/python3.4/site-packages/django/template/base.py", line 910, in render_annotated
    return self.render(context)
  File "/usr/local/lib/python3.4/site-packages/django/template/defaulttags.py", line 211, in render
    nodelist.append(node.render_annotated(context))
  File "/usr/local/lib/python3.4/site-packages/django/template/base.py", line 910, in render_annotated
    return self.render(context)
  File "/usr/local/lib/python3.4/site-packages/django/template/loader_tags.py", line 194, in render
    return template.render(context)
  File "/usr/local/lib/python3.4/site-packages/django/template/base.py", line 177, in render
    return self._render(context)
  File "/usr/local/lib/python3.4/site-packages/django/template/base.py", line 167, in _render
    return self.nodelist.render(context)
  File "/usr/local/lib/python3.4/site-packages/django/template/base.py", line 943, in render
    bit = node.render_annotated(context)
  File "/usr/local/lib/python3.4/site-packages/django/template/base.py", line 910, in render_annotated
    return self.render(context)
  File "/usr/local/lib/python3.4/site-packages/django/template/defaulttags.py", line 211, in render
    nodelist.append(node.render_annotated(context))
  File "/usr/local/lib/python3.4/site-packages/django/template/base.py", line 910, in render_annotated
    return self.render(context)
  File "/usr/local/lib/python3.4/site-packages/django/template/defaulttags.py", line 211, in render
    nodelist.append(node.render_annotated(context))
  File "/usr/local/lib/python3.4/site-packages/django/template/base.py", line 910, in render_annotated
    return self.render(context)
  File "/usr/local/lib/python3.4/site-packages/django/template/defaulttags.py", line 314, in render
    return nodelist.render(context)
  File "/usr/local/lib/python3.4/site-packages/django/template/base.py", line 943, in render
    bit = node.render_annotated(context)
  File "/usr/local/lib/python3.4/site-packages/django/template/base.py", line 910, in render_annotated
    return self.render(context)
  File "/usr/local/lib/python3.4/site-packages/django/template/defaulttags.py", line 314, in render
    return nodelist.render(context)
  File "/usr/local/lib/python3.4/site-packages/django/template/base.py", line 943, in render
    bit = node.render_annotated(context)
  File "/usr/local/lib/python3.4/site-packages/django/template/base.py", line 910, in render_annotated
    return self.render(context)
  File "/usr/local/lib/python3.4/site-packages/django/template/base.py", line 999, in render
    return render_value_in_context(output, context)
  File "/usr/local/lib/python3.4/site-packages/django/template/base.py", line 978, in render_value_in_context
    value = str(value)
  File "/usr/local/lib/python3.4/site-packages/django/utils/html.py", line 380, in <lambda>
    klass.__str__ = lambda self: mark_safe(klass_str(self))
  File "/usr/local/lib/python3.4/site-packages/django/forms/boundfield.py", line 36, in __str__
    return self.as_widget()
  File "/usr/local/lib/python3.4/site-packages/django/forms/boundfield.py", line 118, in as_widget
    **kwargs
  File "/usr/local/lib/python3.4/site-packages/django/forms/widgets.py", line 234, in render
    context = self.get_context(name, value, attrs)
  File "/usr/local/lib/python3.4/site-packages/django/contrib/admin/widgets.py", line 295, in get_context
    'rendered_widget': self.widget.render(name, value, attrs),
  File "/usr/local/lib/python3.4/site-packages/django/forms/widgets.py", line 234, in render
    context = self.get_context(name, value, attrs)
  File "/usr/local/lib/python3.4/site-packages/django/forms/widgets.py", line 677, in get_context
    context = super().get_context(name, value, attrs)
  File "/usr/local/lib/python3.4/site-packages/django/forms/widgets.py", line 637, in get_context
    context['widget']['optgroups'] = self.optgroups(name, context['widget']['value'], attrs)
  File "/usr/local/lib/python3.4/site-packages/django/forms/widgets.py", line 585, in optgroups
    for index, (option_value, option_label) in enumerate(self.choices):
  File "/usr/local/lib/python3.4/site-packages/django/forms/models.py", line 1140, in __iter__
    for obj in queryset:
  File "/usr/local/lib/python3.4/site-packages/django/db/models/query.py", line 336, in _iterator
    yield from self._iterable_class(self, chunked_fetch=use_chunked_fetch, chunk_size=chunk_size)
  File "/usr/local/lib/python3.4/site-packages/django/db/models/query.py", line 53, in __iter__
    results = compiler.execute_sql(chunked_fetch=self.chunked_fetch, chunk_size=self.chunk_size)
  File "/usr/local/lib/python3.4/site-packages/django/db/models/sql/compiler.py", line 1066, in execute_sql
    cursor.execute(sql, params)
  File "/usr/local/lib/python3.4/site-packages/django/db/backends/utils.py", line 100, in execute
    return super().execute(sql, params)
  File "/usr/local/lib/python3.4/site-packages/django/db/backends/utils.py", line 68, in execute
    return self._execute_with_wrappers(sql, params, many=False, executor=self._execute)
  File "/usr/local/lib/python3.4/site-packages/django/db/backends/utils.py", line 77, in _execute_with_wrappers
    return executor(sql, params, many, context)
  File "/usr/local/lib/python3.4/site-packages/django/db/backends/utils.py", line 85, in _execute
    return self.cursor.execute(sql, params)
  File "/usr/local/lib/python3.4/site-packages/django/db/utils.py", line 89, in __exit__
    raise dj_exc_value.with_traceback(traceback) from exc_value
  File "/usr/local/lib/python3.4/site-packages/django/db/backends/utils.py", line 85, in _execute
    return self.cursor.execute(sql, params)
  File "/usr/local/lib/python3.4/site-packages/django/db/backends/sqlite3/base.py", line 303, in execute
    return Database.Cursor.execute(self, query, params)
django.db.utils.OperationalError: no such column: subway_subway.eng_name
[07/Sep/2018 15:30:55] "GET /admin/subway/admins/add/ HTTP/1.1" 500 497307
[07/Sep/2018 15:30:57] "GET /admin/ HTTP/1.1" 200 7473
[07/Sep/2018 15:36:10] "GET /admin/ HTTP/1.1" 200 7473
[07/Sep/2018 15:36:11] "GET /admin/subway/admins/ HTTP/1.1" 200 3249
[07/Sep/2018 15:36:11] "GET /admin/jsi18n/ HTTP/1.1" 200 3185
[07/Sep/2018 15:36:12] "GET /admin/ HTTP/1.1" 200 7473
[07/Sep/2018 15:36:13] "GET /admin/subway/subwaylandmarkpoint/ HTTP/1.1" 200 3350
[07/Sep/2018 15:36:13] "GET /admin/jsi18n/ HTTP/1.1" 200 3185
[07/Sep/2018 15:36:14] "GET /admin/ HTTP/1.1" 200 7473
Internal Server Error: /admin/subway/subway/
Traceback (most recent call last):
  File "/usr/local/lib/python3.4/site-packages/django/db/backends/utils.py", line 85, in _execute
    return self.cursor.execute(sql, params)
  File "/usr/local/lib/python3.4/site-packages/django/db/backends/sqlite3/base.py", line 303, in execute
    return Database.Cursor.execute(self, query, params)
sqlite3.OperationalError: no such column: subway_subway.eng_name

The above exception was the direct cause of the following exception:

Traceback (most recent call last):
  File "/usr/local/lib/python3.4/site-packages/django/core/handlers/exception.py", line 35, in inner
    response = get_response(request)
  File "/usr/local/lib/python3.4/site-packages/django/core/handlers/base.py", line 128, in _get_response
    response = self.process_exception_by_middleware(e, request)
  File "/usr/local/lib/python3.4/site-packages/django/core/handlers/base.py", line 126, in _get_response
    response = wrapped_callback(request, *callback_args, **callback_kwargs)
  File "/usr/local/lib/python3.4/site-packages/django/contrib/admin/options.py", line 574, in wrapper
    return self.admin_site.admin_view(view)(*args, **kwargs)
  File "/usr/local/lib/python3.4/site-packages/django/utils/decorators.py", line 142, in _wrapped_view
    response = view_func(request, *args, **kwargs)
  File "/usr/local/lib/python3.4/site-packages/django/views/decorators/cache.py", line 44, in _wrapped_view_func
    response = view_func(request, *args, **kwargs)
  File "/usr/local/lib/python3.4/site-packages/django/contrib/admin/sites.py", line 223, in inner
    return view(request, *args, **kwargs)
  File "/usr/local/lib/python3.4/site-packages/django/utils/decorators.py", line 62, in _wrapper
    return bound_func(*args, **kwargs)
  File "/usr/local/lib/python3.4/site-packages/django/utils/decorators.py", line 142, in _wrapped_view
    response = view_func(request, *args, **kwargs)
  File "/usr/local/lib/python3.4/site-packages/django/utils/decorators.py", line 58, in bound_func
    return func.__get__(self, type(self))(*args2, **kwargs2)
  File "/usr/local/lib/python3.4/site-packages/django/contrib/admin/options.py", line 1685, in changelist_view
    selection_note=_('0 of %(cnt)s selected') % {'cnt': len(cl.result_list)},
  File "/usr/local/lib/python3.4/site-packages/django/db/models/query.py", line 254, in __len__
    self._fetch_all()
  File "/usr/local/lib/python3.4/site-packages/django/db/models/query.py", line 1179, in _fetch_all
    self._result_cache = list(self._iterable_class(self))
  File "/usr/local/lib/python3.4/site-packages/django/db/models/query.py", line 53, in __iter__
    results = compiler.execute_sql(chunked_fetch=self.chunked_fetch, chunk_size=self.chunk_size)
  File "/usr/local/lib/python3.4/site-packages/django/db/models/sql/compiler.py", line 1066, in execute_sql
    cursor.execute(sql, params)
  File "/usr/local/lib/python3.4/site-packages/django/db/backends/utils.py", line 100, in execute
    return super().execute(sql, params)
  File "/usr/local/lib/python3.4/site-packages/django/db/backends/utils.py", line 68, in execute
    return self._execute_with_wrappers(sql, params, many=False, executor=self._execute)
  File "/usr/local/lib/python3.4/site-packages/django/db/backends/utils.py", line 77, in _execute_with_wrappers
    return executor(sql, params, many, context)
  File "/usr/local/lib/python3.4/site-packages/django/db/backends/utils.py", line 85, in _execute
    return self.cursor.execute(sql, params)
  File "/usr/local/lib/python3.4/site-packages/django/db/utils.py", line 89, in __exit__
    raise dj_exc_value.with_traceback(traceback) from exc_value
  File "/usr/local/lib/python3.4/site-packages/django/db/backends/utils.py", line 85, in _execute
    return self.cursor.execute(sql, params)
  File "/usr/local/lib/python3.4/site-packages/django/db/backends/sqlite3/base.py", line 303, in execute
    return Database.Cursor.execute(self, query, params)
django.db.utils.OperationalError: no such column: subway_subway.eng_name
[07/Sep/2018 15:36:15] "GET /admin/subway/subway/ HTTP/1.1" 500 161940
[07/Sep/2018 15:36:18] "GET /admin/ HTTP/1.1" 200 7473
Internal Server Error: /insert
Traceback (most recent call last):
  File "/usr/local/lib/python3.4/site-packages/django/db/backends/utils.py", line 85, in _execute
    return self.cursor.execute(sql, params)
  File "/usr/local/lib/python3.4/site-packages/django/db/backends/sqlite3/base.py", line 303, in execute
    return Database.Cursor.execute(self, query, params)
sqlite3.OperationalError: table subway_subway has no column named eng_name

The above exception was the direct cause of the following exception:

Traceback (most recent call last):
  File "/usr/local/lib/python3.4/site-packages/django/core/handlers/exception.py", line 35, in inner
    response = get_response(request)
  File "/usr/local/lib/python3.4/site-packages/django/core/handlers/base.py", line 128, in _get_response
    response = self.process_exception_by_middleware(e, request)
  File "/usr/local/lib/python3.4/site-packages/django/core/handlers/base.py", line 126, in _get_response
    response = wrapped_callback(request, *callback_args, **callback_kwargs)
  File "/home/ubuntu/myproject/subway/views.py", line 157, in insert_station_datas
    Subway().insert_stations(data, line, station)
  File "/home/ubuntu/myproject/subway/models.py", line 37, in insert_stations
    self.save()
  File "/usr/local/lib/python3.4/site-packages/django/db/models/base.py", line 729, in save
    force_update=force_update, update_fields=update_fields)
  File "/usr/local/lib/python3.4/site-packages/django/db/models/base.py", line 759, in save_base
    updated = self._save_table(raw, cls, force_insert, force_update, using, update_fields)
  File "/usr/local/lib/python3.4/site-packages/django/db/models/base.py", line 842, in _save_table
    result = self._do_insert(cls._base_manager, using, fields, update_pk, raw)
  File "/usr/local/lib/python3.4/site-packages/django/db/models/base.py", line 880, in _do_insert
    using=using, raw=raw)
  File "/usr/local/lib/python3.4/site-packages/django/db/models/manager.py", line 82, in manager_method
    return getattr(self.get_queryset(), name)(*args, **kwargs)
  File "/usr/local/lib/python3.4/site-packages/django/db/models/query.py", line 1125, in _insert
    return query.get_compiler(using=using).execute_sql(return_id)
  File "/usr/local/lib/python3.4/site-packages/django/db/models/sql/compiler.py", line 1283, in execute_sql
    cursor.execute(sql, params)
  File "/usr/local/lib/python3.4/site-packages/django/db/backends/utils.py", line 100, in execute
    return super().execute(sql, params)
  File "/usr/local/lib/python3.4/site-packages/django/db/backends/utils.py", line 68, in execute
    return self._execute_with_wrappers(sql, params, many=False, executor=self._execute)
  File "/usr/local/lib/python3.4/site-packages/django/db/backends/utils.py", line 77, in _execute_with_wrappers
    return executor(sql, params, many, context)
  File "/usr/local/lib/python3.4/site-packages/django/db/backends/utils.py", line 85, in _execute
    return self.cursor.execute(sql, params)
  File "/usr/local/lib/python3.4/site-packages/django/db/utils.py", line 89, in __exit__
    raise dj_exc_value.with_traceback(traceback) from exc_value
  File "/usr/local/lib/python3.4/site-packages/django/db/backends/utils.py", line 85, in _execute
    return self.cursor.execute(sql, params)
  File "/usr/local/lib/python3.4/site-packages/django/db/backends/sqlite3/base.py", line 303, in execute
    return Database.Cursor.execute(self, query, params)
django.db.utils.OperationalError: table subway_subway has no column named eng_name
[07/Sep/2018 15:37:17] "GET /insert HTTP/1.1" 500 161374
[07/Sep/2018 15:37:25] "GET /admin/ HTTP/1.1" 200 7473
[07/Sep/2018 15:37:27] "GET /admin/ HTTP/1.1" 200 7473
Internal Server Error: /admin/subway/subway/
Traceback (most recent call last):
  File "/usr/local/lib/python3.4/site-packages/django/db/backends/utils.py", line 85, in _execute
    return self.cursor.execute(sql, params)
  File "/usr/local/lib/python3.4/site-packages/django/db/backends/sqlite3/base.py", line 303, in execute
    return Database.Cursor.execute(self, query, params)
sqlite3.OperationalError: no such column: subway_subway.eng_name

The above exception was the direct cause of the following exception:

Traceback (most recent call last):
  File "/usr/local/lib/python3.4/site-packages/django/core/handlers/exception.py", line 35, in inner
    response = get_response(request)
  File "/usr/local/lib/python3.4/site-packages/django/core/handlers/base.py", line 128, in _get_response
    response = self.process_exception_by_middleware(e, request)
  File "/usr/local/lib/python3.4/site-packages/django/core/handlers/base.py", line 126, in _get_response
    response = wrapped_callback(request, *callback_args, **callback_kwargs)
  File "/usr/local/lib/python3.4/site-packages/django/contrib/admin/options.py", line 574, in wrapper
    return self.admin_site.admin_view(view)(*args, **kwargs)
  File "/usr/local/lib/python3.4/site-packages/django/utils/decorators.py", line 142, in _wrapped_view
    response = view_func(request, *args, **kwargs)
  File "/usr/local/lib/python3.4/site-packages/django/views/decorators/cache.py", line 44, in _wrapped_view_func
    response = view_func(request, *args, **kwargs)
  File "/usr/local/lib/python3.4/site-packages/django/contrib/admin/sites.py", line 223, in inner
    return view(request, *args, **kwargs)
  File "/usr/local/lib/python3.4/site-packages/django/utils/decorators.py", line 62, in _wrapper
    return bound_func(*args, **kwargs)
  File "/usr/local/lib/python3.4/site-packages/django/utils/decorators.py", line 142, in _wrapped_view
    response = view_func(request, *args, **kwargs)
  File "/usr/local/lib/python3.4/site-packages/django/utils/decorators.py", line 58, in bound_func
    return func.__get__(self, type(self))(*args2, **kwargs2)
  File "/usr/local/lib/python3.4/site-packages/django/contrib/admin/options.py", line 1685, in changelist_view
    selection_note=_('0 of %(cnt)s selected') % {'cnt': len(cl.result_list)},
  File "/usr/local/lib/python3.4/site-packages/django/db/models/query.py", line 254, in __len__
    self._fetch_all()
  File "/usr/local/lib/python3.4/site-packages/django/db/models/query.py", line 1179, in _fetch_all
    self._result_cache = list(self._iterable_class(self))
  File "/usr/local/lib/python3.4/site-packages/django/db/models/query.py", line 53, in __iter__
    results = compiler.execute_sql(chunked_fetch=self.chunked_fetch, chunk_size=self.chunk_size)
  File "/usr/local/lib/python3.4/site-packages/django/db/models/sql/compiler.py", line 1066, in execute_sql
    cursor.execute(sql, params)
  File "/usr/local/lib/python3.4/site-packages/django/db/backends/utils.py", line 100, in execute
    return super().execute(sql, params)
  File "/usr/local/lib/python3.4/site-packages/django/db/backends/utils.py", line 68, in execute
    return self._execute_with_wrappers(sql, params, many=False, executor=self._execute)
  File "/usr/local/lib/python3.4/site-packages/django/db/backends/utils.py", line 77, in _execute_with_wrappers
    return executor(sql, params, many, context)
  File "/usr/local/lib/python3.4/site-packages/django/db/backends/utils.py", line 85, in _execute
    return self.cursor.execute(sql, params)
  File "/usr/local/lib/python3.4/site-packages/django/db/utils.py", line 89, in __exit__
    raise dj_exc_value.with_traceback(traceback) from exc_value
  File "/usr/local/lib/python3.4/site-packages/django/db/backends/utils.py", line 85, in _execute
    return self.cursor.execute(sql, params)
  File "/usr/local/lib/python3.4/site-packages/django/db/backends/sqlite3/base.py", line 303, in execute
    return Database.Cursor.execute(self, query, params)
django.db.utils.OperationalError: no such column: subway_subway.eng_name
[07/Sep/2018 15:37:28] "GET /admin/subway/subway/ HTTP/1.1" 500 161934
[07/Sep/2018 15:37:29] "GET /admin/ HTTP/1.1" 200 7473
Internal Server Error: /admin/subway/subway/
Traceback (most recent call last):
  File "/usr/local/lib/python3.4/site-packages/django/db/backends/utils.py", line 85, in _execute
    return self.cursor.execute(sql, params)
  File "/usr/local/lib/python3.4/site-packages/django/db/backends/sqlite3/base.py", line 303, in execute
    return Database.Cursor.execute(self, query, params)
sqlite3.OperationalError: no such table: subway_subway

The above exception was the direct cause of the following exception:

Traceback (most recent call last):
  File "/usr/local/lib/python3.4/site-packages/django/core/handlers/exception.py", line 35, in inner
    response = get_response(request)
  File "/usr/local/lib/python3.4/site-packages/django/core/handlers/base.py", line 128, in _get_response
    response = self.process_exception_by_middleware(e, request)
  File "/usr/local/lib/python3.4/site-packages/django/core/handlers/base.py", line 126, in _get_response
    response = wrapped_callback(request, *callback_args, **callback_kwargs)
  File "/usr/local/lib/python3.4/site-packages/django/contrib/admin/options.py", line 574, in wrapper
    return self.admin_site.admin_view(view)(*args, **kwargs)
  File "/usr/local/lib/python3.4/site-packages/django/utils/decorators.py", line 142, in _wrapped_view
    response = view_func(request, *args, **kwargs)
  File "/usr/local/lib/python3.4/site-packages/django/views/decorators/cache.py", line 44, in _wrapped_view_func
    response = view_func(request, *args, **kwargs)
  File "/usr/local/lib/python3.4/site-packages/django/contrib/admin/sites.py", line 223, in inner
    return view(request, *args, **kwargs)
  File "/usr/local/lib/python3.4/site-packages/django/utils/decorators.py", line 62, in _wrapper
    return bound_func(*args, **kwargs)
  File "/usr/local/lib/python3.4/site-packages/django/utils/decorators.py", line 142, in _wrapped_view
    response = view_func(request, *args, **kwargs)
  File "/usr/local/lib/python3.4/site-packages/django/utils/decorators.py", line 58, in bound_func
    return func.__get__(self, type(self))(*args2, **kwargs2)
  File "/usr/local/lib/python3.4/site-packages/django/contrib/admin/options.py", line 1570, in changelist_view
    cl = self.get_changelist_instance(request)
  File "/usr/local/lib/python3.4/site-packages/django/contrib/admin/options.py", line 705, in get_changelist_instance
    self,
  File "/usr/local/lib/python3.4/site-packages/django/contrib/admin/views/main.py", line 77, in __init__
    self.get_results(request)
  File "/usr/local/lib/python3.4/site-packages/django/contrib/admin/views/main.py", line 175, in get_results
    result_count = paginator.count
  File "/usr/local/lib/python3.4/site-packages/django/utils/functional.py", line 36, in __get__
    res = instance.__dict__[self.name] = self.func(instance)
  File "/usr/local/lib/python3.4/site-packages/django/core/paginator.py", line 85, in count
    return self.object_list.count()
  File "/usr/local/lib/python3.4/site-packages/django/db/models/query.py", line 387, in count
    return self.query.get_count(using=self.db)
  File "/usr/local/lib/python3.4/site-packages/django/db/models/sql/query.py", line 491, in get_count
    number = obj.get_aggregation(using, ['__count'])['__count']
  File "/usr/local/lib/python3.4/site-packages/django/db/models/sql/query.py", line 476, in get_aggregation
    result = compiler.execute_sql(SINGLE)
  File "/usr/local/lib/python3.4/site-packages/django/db/models/sql/compiler.py", line 1066, in execute_sql
    cursor.execute(sql, params)
  File "/usr/local/lib/python3.4/site-packages/django/db/backends/utils.py", line 100, in execute
    return super().execute(sql, params)
  File "/usr/local/lib/python3.4/site-packages/django/db/backends/utils.py", line 68, in execute
    return self._execute_with_wrappers(sql, params, many=False, executor=self._execute)
  File "/usr/local/lib/python3.4/site-packages/django/db/backends/utils.py", line 77, in _execute_with_wrappers
    return executor(sql, params, many, context)
  File "/usr/local/lib/python3.4/site-packages/django/db/backends/utils.py", line 85, in _execute
    return self.cursor.execute(sql, params)
  File "/usr/local/lib/python3.4/site-packages/django/db/utils.py", line 89, in __exit__
    raise dj_exc_value.with_traceback(traceback) from exc_value
  File "/usr/local/lib/python3.4/site-packages/django/db/backends/utils.py", line 85, in _execute
    return self.cursor.execute(sql, params)
  File "/usr/local/lib/python3.4/site-packages/django/db/backends/sqlite3/base.py", line 303, in execute
    return Database.Cursor.execute(self, query, params)
django.db.utils.OperationalError: no such table: subway_subway
[07/Sep/2018 15:41:33] "GET /admin/subway/subway/ HTTP/1.1" 500 178389
[07/Sep/2018 15:41:38] "GET /admin/ HTTP/1.1" 200 7473
[07/Sep/2018 15:41:38] "GET /admin/ HTTP/1.1" 200 7473
Internal Server Error: /admin/subway/subway/
Traceback (most recent call last):
  File "/usr/local/lib/python3.4/site-packages/django/db/backends/utils.py", line 85, in _execute
    return self.cursor.execute(sql, params)
  File "/usr/local/lib/python3.4/site-packages/django/db/backends/sqlite3/base.py", line 303, in execute
    return Database.Cursor.execute(self, query, params)
sqlite3.OperationalError: no such table: subway_subway

The above exception was the direct cause of the following exception:

Traceback (most recent call last):
  File "/usr/local/lib/python3.4/site-packages/django/core/handlers/exception.py", line 35, in inner
    response = get_response(request)
  File "/usr/local/lib/python3.4/site-packages/django/core/handlers/base.py", line 128, in _get_response
    response = self.process_exception_by_middleware(e, request)
  File "/usr/local/lib/python3.4/site-packages/django/core/handlers/base.py", line 126, in _get_response
    response = wrapped_callback(request, *callback_args, **callback_kwargs)
  File "/usr/local/lib/python3.4/site-packages/django/contrib/admin/options.py", line 574, in wrapper
    return self.admin_site.admin_view(view)(*args, **kwargs)
  File "/usr/local/lib/python3.4/site-packages/django/utils/decorators.py", line 142, in _wrapped_view
    response = view_func(request, *args, **kwargs)
  File "/usr/local/lib/python3.4/site-packages/django/views/decorators/cache.py", line 44, in _wrapped_view_func
    response = view_func(request, *args, **kwargs)
  File "/usr/local/lib/python3.4/site-packages/django/contrib/admin/sites.py", line 223, in inner
    return view(request, *args, **kwargs)
  File "/usr/local/lib/python3.4/site-packages/django/utils/decorators.py", line 62, in _wrapper
    return bound_func(*args, **kwargs)
  File "/usr/local/lib/python3.4/site-packages/django/utils/decorators.py", line 142, in _wrapped_view
    response = view_func(request, *args, **kwargs)
  File "/usr/local/lib/python3.4/site-packages/django/utils/decorators.py", line 58, in bound_func
    return func.__get__(self, type(self))(*args2, **kwargs2)
  File "/usr/local/lib/python3.4/site-packages/django/contrib/admin/options.py", line 1570, in changelist_view
    cl = self.get_changelist_instance(request)
  File "/usr/local/lib/python3.4/site-packages/django/contrib/admin/options.py", line 705, in get_changelist_instance
    self,
  File "/usr/local/lib/python3.4/site-packages/django/contrib/admin/views/main.py", line 77, in __init__
    self.get_results(request)
  File "/usr/local/lib/python3.4/site-packages/django/contrib/admin/views/main.py", line 175, in get_results
    result_count = paginator.count
  File "/usr/local/lib/python3.4/site-packages/django/utils/functional.py", line 36, in __get__
    res = instance.__dict__[self.name] = self.func(instance)
  File "/usr/local/lib/python3.4/site-packages/django/core/paginator.py", line 85, in count
    return self.object_list.count()
  File "/usr/local/lib/python3.4/site-packages/django/db/models/query.py", line 387, in count
    return self.query.get_count(using=self.db)
  File "/usr/local/lib/python3.4/site-packages/django/db/models/sql/query.py", line 491, in get_count
    number = obj.get_aggregation(using, ['__count'])['__count']
  File "/usr/local/lib/python3.4/site-packages/django/db/models/sql/query.py", line 476, in get_aggregation
    result = compiler.execute_sql(SINGLE)
  File "/usr/local/lib/python3.4/site-packages/django/db/models/sql/compiler.py", line 1066, in execute_sql
    cursor.execute(sql, params)
  File "/usr/local/lib/python3.4/site-packages/django/db/backends/utils.py", line 100, in execute
    return super().execute(sql, params)
  File "/usr/local/lib/python3.4/site-packages/django/db/backends/utils.py", line 68, in execute
    return self._execute_with_wrappers(sql, params, many=False, executor=self._execute)
  File "/usr/local/lib/python3.4/site-packages/django/db/backends/utils.py", line 77, in _execute_with_wrappers
    return executor(sql, params, many, context)
  File "/usr/local/lib/python3.4/site-packages/django/db/backends/utils.py", line 85, in _execute
    return self.cursor.execute(sql, params)
  File "/usr/local/lib/python3.4/site-packages/django/db/utils.py", line 89, in __exit__
    raise dj_exc_value.with_traceback(traceback) from exc_value
  File "/usr/local/lib/python3.4/site-packages/django/db/backends/utils.py", line 85, in _execute
    return self.cursor.execute(sql, params)
  File "/usr/local/lib/python3.4/site-packages/django/db/backends/sqlite3/base.py", line 303, in execute
    return Database.Cursor.execute(self, query, params)
django.db.utils.OperationalError: no such table: subway_subway
[07/Sep/2018 15:41:45] "GET /admin/subway/subway/ HTTP/1.1" 500 178255
[07/Sep/2018 15:41:53] "GET /admin/ HTTP/1.1" 200 7473
Internal Server Error: /admin/subway/subwaylandmarkpoint/
Traceback (most recent call last):
  File "/usr/local/lib/python3.4/site-packages/django/db/backends/utils.py", line 85, in _execute
    return self.cursor.execute(sql, params)
  File "/usr/local/lib/python3.4/site-packages/django/db/backends/sqlite3/base.py", line 303, in execute
    return Database.Cursor.execute(self, query, params)
sqlite3.OperationalError: no such table: subway_subwaylandmarkpoint

The above exception was the direct cause of the following exception:

Traceback (most recent call last):
  File "/usr/local/lib/python3.4/site-packages/django/core/handlers/exception.py", line 35, in inner
    response = get_response(request)
  File "/usr/local/lib/python3.4/site-packages/django/core/handlers/base.py", line 128, in _get_response
    response = self.process_exception_by_middleware(e, request)
  File "/usr/local/lib/python3.4/site-packages/django/core/handlers/base.py", line 126, in _get_response
    response = wrapped_callback(request, *callback_args, **callback_kwargs)
  File "/usr/local/lib/python3.4/site-packages/django/contrib/admin/options.py", line 574, in wrapper
    return self.admin_site.admin_view(view)(*args, **kwargs)
  File "/usr/local/lib/python3.4/site-packages/django/utils/decorators.py", line 142, in _wrapped_view
    response = view_func(request, *args, **kwargs)
  File "/usr/local/lib/python3.4/site-packages/django/views/decorators/cache.py", line 44, in _wrapped_view_func
    response = view_func(request, *args, **kwargs)
  File "/usr/local/lib/python3.4/site-packages/django/contrib/admin/sites.py", line 223, in inner
    return view(request, *args, **kwargs)
  File "/usr/local/lib/python3.4/site-packages/django/utils/decorators.py", line 62, in _wrapper
    return bound_func(*args, **kwargs)
  File "/usr/local/lib/python3.4/site-packages/django/utils/decorators.py", line 142, in _wrapped_view
    response = view_func(request, *args, **kwargs)
  File "/usr/local/lib/python3.4/site-packages/django/utils/decorators.py", line 58, in bound_func
    return func.__get__(self, type(self))(*args2, **kwargs2)
  File "/usr/local/lib/python3.4/site-packages/django/contrib/admin/options.py", line 1570, in changelist_view
    cl = self.get_changelist_instance(request)
  File "/usr/local/lib/python3.4/site-packages/django/contrib/admin/options.py", line 705, in get_changelist_instance
    self,
  File "/usr/local/lib/python3.4/site-packages/django/contrib/admin/views/main.py", line 77, in __init__
    self.get_results(request)
  File "/usr/local/lib/python3.4/site-packages/django/contrib/admin/views/main.py", line 175, in get_results
    result_count = paginator.count
  File "/usr/local/lib/python3.4/site-packages/django/utils/functional.py", line 36, in __get__
    res = instance.__dict__[self.name] = self.func(instance)
  File "/usr/local/lib/python3.4/site-packages/django/core/paginator.py", line 85, in count
    return self.object_list.count()
  File "/usr/local/lib/python3.4/site-packages/django/db/models/query.py", line 387, in count
    return self.query.get_count(using=self.db)
  File "/usr/local/lib/python3.4/site-packages/django/db/models/sql/query.py", line 491, in get_count
    number = obj.get_aggregation(using, ['__count'])['__count']
  File "/usr/local/lib/python3.4/site-packages/django/db/models/sql/query.py", line 476, in get_aggregation
    result = compiler.execute_sql(SINGLE)
  File "/usr/local/lib/python3.4/site-packages/django/db/models/sql/compiler.py", line 1066, in execute_sql
    cursor.execute(sql, params)
  File "/usr/local/lib/python3.4/site-packages/django/db/backends/utils.py", line 100, in execute
    return super().execute(sql, params)
  File "/usr/local/lib/python3.4/site-packages/django/db/backends/utils.py", line 68, in execute
    return self._execute_with_wrappers(sql, params, many=False, executor=self._execute)
  File "/usr/local/lib/python3.4/site-packages/django/db/backends/utils.py", line 77, in _execute_with_wrappers
    return executor(sql, params, many, context)
  File "/usr/local/lib/python3.4/site-packages/django/db/backends/utils.py", line 85, in _execute
    return self.cursor.execute(sql, params)
  File "/usr/local/lib/python3.4/site-packages/django/db/utils.py", line 89, in __exit__
    raise dj_exc_value.with_traceback(traceback) from exc_value
  File "/usr/local/lib/python3.4/site-packages/django/db/backends/utils.py", line 85, in _execute
    return self.cursor.execute(sql, params)
  File "/usr/local/lib/python3.4/site-packages/django/db/backends/sqlite3/base.py", line 303, in execute
    return Database.Cursor.execute(self, query, params)
django.db.utils.OperationalError: no such table: subway_subwaylandmarkpoint
[07/Sep/2018 15:42:20] "GET /admin/subway/subwaylandmarkpoint/ HTTP/1.1" 500 178814
